2019-08-04 16:40:25,859 ERROR Exception on /explore [GET] [in c:\users\user\documents\microblog\venv\lib\site-packages\flask\app.py:(lineno)d]
Traceback (most recent call last):
  File "c:\users\user\documents\microblog\venv\lib\site-packages\flask\app.py", line 2292, in wsgi_app
    response = self.full_dispatch_request()
  File "c:\users\user\documents\microblog\venv\lib\site-packages\flask\app.py", line 1815, in full_dispatch_request
    rv = self.handle_user_exception(e)
  File "c:\users\user\documents\microblog\venv\lib\site-packages\flask\app.py", line 1718, in handle_user_exception
    reraise(exc_type, exc_value, tb)
  File "c:\users\user\documents\microblog\venv\lib\site-packages\flask\_compat.py", line 35, in reraise
    raise value
  File "c:\users\user\documents\microblog\venv\lib\site-packages\flask\app.py", line 1813, in full_dispatch_request
    rv = self.dispatch_request()
  File "c:\users\user\documents\microblog\venv\lib\site-packages\flask\app.py", line 1799, in dispatch_request
    return self.view_functions[rule.endpoint](**req.view_args)
  File "c:\users\user\documents\microblog\venv\lib\site-packages\flask_login\utils.py", line 261, in decorated_view
    return func(*args, **kwargs)
  File "C:\Users\user\Documents\microblog\app\routes.py", line 246, in explore
    next_url=next_url, prev_url=prev_url)
  File "c:\users\user\documents\microblog\venv\lib\site-packages\flask\templating.py", line 135, in render_template
    context, ctx.app)
  File "c:\users\user\documents\microblog\venv\lib\site-packages\flask\templating.py", line 117, in _render
    rv = template.render(context)
  File "c:\users\user\documents\microblog\venv\lib\site-packages\jinja2\asyncsupport.py", line 76, in render
    return original_render(self, *args, **kwargs)
  File "c:\users\user\documents\microblog\venv\lib\site-packages\jinja2\environment.py", line 1008, in render
    return self.environment.handle_exception(exc_info, True)
  File "c:\users\user\documents\microblog\venv\lib\site-packages\jinja2\environment.py", line 780, in handle_exception
    reraise(exc_type, exc_value, tb)
  File "c:\users\user\documents\microblog\venv\lib\site-packages\jinja2\_compat.py", line 37, in reraise
    raise value.with_traceback(tb)
  File "C:\Users\user\Documents\microblog\app\templates\index.html", line 1, in top-level template code
    {% extends "base.html" %}
  File "C:\Users\user\Documents\microblog\app\templates\base.html", line 36, in top-level template code
    {% block content %}{% endblock %}
  File "C:\Users\user\Documents\microblog\app\templates\index.html", line 22, in block "content"
    {% include '_post.html' %}
  File "C:\Users\user\Documents\microblog\app\templates\_post.html", line 4, in top-level template code
    <td><img src="{{ post.author.avatar(36) }}"></td>
jinja2.exceptions.UndefinedError: 'None' has no attribute 'avatar'
2019-08-04 18:15:33,190 INFO Microblog startup [in C:\Users\user\Documents\microblog\app\__init__.py:(lineno)d]
2019-08-04 18:16:12,451 INFO Microblog startup [in C:\Users\user\Documents\microblog\app\__init__.py:(lineno)d]
2019-08-04 18:20:03,946 INFO Microblog startup [in C:\Users\user\Documents\microblog\app\__init__.py:(lineno)d]
2019-08-04 18:43:04,329 INFO Microblog startup [in C:\Users\user\Documents\microblog\app\__init__.py:(lineno)d]
2019-08-04 18:43:08,766 ERROR Exception on /user/xyz [GET] [in c:\users\user\documents\microblog\venv\lib\site-packages\flask\app.py:(lineno)d]
Traceback (most recent call last):
  File "c:\users\user\documents\microblog\venv\lib\site-packages\flask\app.py", line 2292, in wsgi_app
    response = self.full_dispatch_request()
  File "c:\users\user\documents\microblog\venv\lib\site-packages\flask\app.py", line 1815, in full_dispatch_request
    rv = self.handle_user_exception(e)
  File "c:\users\user\documents\microblog\venv\lib\site-packages\flask\app.py", line 1718, in handle_user_exception
    reraise(exc_type, exc_value, tb)
  File "c:\users\user\documents\microblog\venv\lib\site-packages\flask\_compat.py", line 35, in reraise
    raise value
  File "c:\users\user\documents\microblog\venv\lib\site-packages\flask\app.py", line 1813, in full_dispatch_request
    rv = self.dispatch_request()
  File "c:\users\user\documents\microblog\venv\lib\site-packages\flask\app.py", line 1799, in dispatch_request
    return self.view_functions[rule.endpoint](**req.view_args)
  File "c:\users\user\documents\microblog\venv\lib\site-packages\flask_login\utils.py", line 261, in decorated_view
    return func(*args, **kwargs)
  File "C:\Users\user\Documents\microblog\app\routes.py", line 125, in user
    prev_url=prev_url, next_url=next_url)
  File "c:\users\user\documents\microblog\venv\lib\site-packages\flask\templating.py", line 135, in render_template
    context, ctx.app)
  File "c:\users\user\documents\microblog\venv\lib\site-packages\flask\templating.py", line 117, in _render
    rv = template.render(context)
  File "c:\users\user\documents\microblog\venv\lib\site-packages\jinja2\asyncsupport.py", line 76, in render
    return original_render(self, *args, **kwargs)
  File "c:\users\user\documents\microblog\venv\lib\site-packages\jinja2\environment.py", line 1008, in render
    return self.environment.handle_exception(exc_info, True)
  File "c:\users\user\documents\microblog\venv\lib\site-packages\jinja2\environment.py", line 780, in handle_exception
    reraise(exc_type, exc_value, tb)
  File "c:\users\user\documents\microblog\venv\lib\site-packages\jinja2\_compat.py", line 37, in reraise
    raise value.with_traceback(tb)
  File "C:\Users\user\Documents\microblog\app\templates\base.html", line 54, in template
    {% block content %}
  File "c:\users\user\documents\microblog\venv\lib\site-packages\jinja2\environment.py", line 1005, in render
    return concat(self.root_render_func(self.new_context(vars)))
  File "C:\Users\user\Documents\microblog\app\templates\user.html", line 1, in top-level template code
    {% extends "base.html" %}
  File "c:\users\user\documents\microblog\venv\lib\site-packages\jinja2\environment.py", line 780, in handle_exception
    reraise(exc_type, exc_value, tb)
  File "c:\users\user\documents\microblog\venv\lib\site-packages\jinja2\_compat.py", line 37, in reraise
    raise value.with_traceback(tb)
  File "C:\Users\user\Documents\microblog\app\templates\base.html", line 54, in template
    {% block content %}
  File "c:\users\user\documents\microblog\venv\lib\site-packages\jinja2\environment.py", line 543, in _generate
    optimized=self.optimized)
  File "c:\users\user\documents\microblog\venv\lib\site-packages\jinja2\compiler.py", line 82, in generate
    generator.visit(node)
  File "c:\users\user\documents\microblog\venv\lib\site-packages\jinja2\visitor.py", line 38, in visit
    return f(node, *args, **kwargs)
  File "c:\users\user\documents\microblog\venv\lib\site-packages\jinja2\compiler.py", line 718, in visit_Template
    self.fail('block %r defined twice' % block.name, block.lineno)
  File "c:\users\user\documents\microblog\venv\lib\site-packages\jinja2\compiler.py", line 315, in fail
    raise TemplateAssertionError(msg, lineno, self.name, self.filename)
jinja2.exceptions.TemplateAssertionError: block 'content' defined twice
2019-08-04 18:45:23,770 INFO Microblog startup [in C:\Users\user\Documents\microblog\app\__init__.py:(lineno)d]
