 ]
 2019-07-16 06:57:38,469 INFO: Microblog startup [in C:\Users\DELL\Desktop\microblog\app\__init__.py:43]
2019-07-16 06:58:56,909 ERROR: Exception on /edit_profile.html [POST] [in c:\users\dell\desktop\microblog\venv\lib\site-packages\flask\app.py:1761]
Traceback (most recent call last):
  File "c:\users\dell\desktop\microblog\venv\lib\site-packages\sqlalchemy\engine\base.py", line 1244, in _execute_context
    cursor, statement, parameters, context
  File "c:\users\dell\desktop\microblog\venv\lib\site-packages\sqlalchemy\engine\default.py", line 550, in do_execute
    cursor.execute(statement, parameters)
sqlite3.IntegrityError: UNIQUE constraint failed: user.username

The above exception was the direct cause of the following exception:

Traceback (most recent call last):
  File "c:\users\dell\desktop\microblog\venv\lib\site-packages\flask\app.py", line 2292, in wsgi_app
    response = self.full_dispatch_request()
  File "c:\users\dell\desktop\microblog\venv\lib\site-packages\flask\app.py", line 1815, in full_dispatch_request
    rv = self.handle_user_exception(e)
  File "c:\users\dell\desktop\microblog\venv\lib\site-packages\flask\app.py", line 1718, in handle_user_exception
    reraise(exc_type, exc_value, tb)
  File "c:\users\dell\desktop\microblog\venv\lib\site-packages\flask\_compat.py", line 35, in reraise
    raise value
  File "c:\users\dell\desktop\microblog\venv\lib\site-packages\flask\app.py", line 1813, in full_dispatch_request
    rv = self.dispatch_request()
  File "c:\users\dell\desktop\microblog\venv\lib\site-packages\flask\app.py", line 1799, in dispatch_request
    return self.view_functions[rule.endpoint](**req.view_args)
  File "c:\users\dell\desktop\microblog\venv\lib\site-packages\flask_login\utils.py", line 261, in decorated_view
    return func(*args, **kwargs)
  File "C:\Users\DELL\Desktop\microblog\app\routes.py", line 92, in edit_profile
    db.session.commit()
  File "c:\users\dell\desktop\microblog\venv\lib\site-packages\sqlalchemy\orm\scoping.py", line 162, in do
    return getattr(self.registry(), name)(*args, **kwargs)
  File "c:\users\dell\desktop\microblog\venv\lib\site-packages\sqlalchemy\orm\session.py", line 1026, in commit
    self.transaction.commit()
  File "c:\users\dell\desktop\microblog\venv\lib\site-packages\sqlalchemy\orm\session.py", line 493, in commit
    self._prepare_impl()
  File "c:\users\dell\desktop\microblog\venv\lib\site-packages\sqlalchemy\orm\session.py", line 472, in _prepare_impl
    self.session.flush()
  File "c:\users\dell\desktop\microblog\venv\lib\site-packages\sqlalchemy\orm\session.py", line 2458, in flush
    self._flush(objects)
  File "c:\users\dell\desktop\microblog\venv\lib\site-packages\sqlalchemy\orm\session.py", line 2596, in _flush
    transaction.rollback(_capture_exception=True)
  File "c:\users\dell\desktop\microblog\venv\lib\site-packages\sqlalchemy\util\langhelpers.py", line 68, in __exit__
    compat.reraise(exc_type, exc_value, exc_tb)
  File "c:\users\dell\desktop\microblog\venv\lib\site-packages\sqlalchemy\util\compat.py", line 129, in reraise
    raise value
  File "c:\users\dell\desktop\microblog\venv\lib\site-packages\sqlalchemy\orm\session.py", line 2556, in _flush
    flush_context.execute()
  File "c:\users\dell\desktop\microblog\venv\lib\site-packages\sqlalchemy\orm\unitofwork.py", line 422, in execute
    rec.execute(self)
  File "c:\users\dell\desktop\microblog\venv\lib\site-packages\sqlalchemy\orm\unitofwork.py", line 589, in execute
    uow,
  File "c:\users\dell\desktop\microblog\venv\lib\site-packages\sqlalchemy\orm\persistence.py", line 236, in save_obj
    update,
  File "c:\users\dell\desktop\microblog\venv\lib\site-packages\sqlalchemy\orm\persistence.py", line 978, in _emit_update_statements
    statement, multiparams
  File "c:\users\dell\desktop\microblog\venv\lib\site-packages\sqlalchemy\engine\base.py", line 988, in execute
    return meth(self, multiparams, params)
  File "c:\users\dell\desktop\microblog\venv\lib\site-packages\sqlalchemy\sql\elements.py", line 287, in _execute_on_connection
    return connection._execute_clauseelement(self, multiparams, params)
  File "c:\users\dell\desktop\microblog\venv\lib\site-packages\sqlalchemy\engine\base.py", line 1107, in _execute_clauseelement
    distilled_params,
  File "c:\users\dell\desktop\microblog\venv\lib\site-packages\sqlalchemy\engine\base.py", line 1248, in _execute_context
    e, statement, parameters, cursor, context
  File "c:\users\dell\desktop\microblog\venv\lib\site-packages\sqlalchemy\engine\base.py", line 1466, in _handle_dbapi_exception
    util.raise_from_cause(sqlalchemy_exception, exc_info)
  File "c:\users\dell\desktop\microblog\venv\lib\site-packages\sqlalchemy\util\compat.py", line 383, in raise_from_cause
    reraise(type(exception), exception, tb=exc_tb, cause=cause)
  File "c:\users\dell\desktop\microblog\venv\lib\site-packages\sqlalchemy\util\compat.py", line 128, in reraise
    raise value.with_traceback(tb)
  File "c:\users\dell\desktop\microblog\venv\lib\site-packages\sqlalchemy\engine\base.py", line 1244, in _execute_context
    cursor, statement, parameters, context
  File "c:\users\dell\desktop\microblog\venv\lib\site-packages\sqlalchemy\engine\default.py", line 550, in do_execute
    cursor.execute(statement, parameters)
sqlalchemy.exc.IntegrityError: (sqlite3.IntegrityError) UNIQUE constraint failed: user.username
[SQL: UPDATE user SET username=?, about_me=? WHERE user.id = ?]
[parameters: ('makavelli', 'jazx', 10)]
(Background on this error at: http://sqlalche.me/e/gkpj)
2019-07-16 08:14:56,768 INFO: Microblog startup [in C:\Users\DELL\Desktop\microblog\app\__init__.py:43]
2019-07-16 08:15:13,805 ERROR: Exception on /edit_profile.html [GET] [in c:\users\dell\desktop\microblog\venv\lib\site-packages\flask\app.py:1761]
Traceback (most recent call last):
  File "c:\users\dell\desktop\microblog\venv\lib\site-packages\flask\app.py", line 2292, in wsgi_app
    response = self.full_dispatch_request()
  File "c:\users\dell\desktop\microblog\venv\lib\site-packages\flask\app.py", line 1815, in full_dispatch_request
    rv = self.handle_user_exception(e)
  File "c:\users\dell\desktop\microblog\venv\lib\site-packages\flask\app.py", line 1718, in handle_user_exception
    reraise(exc_type, exc_value, tb)
  File "c:\users\dell\desktop\microblog\venv\lib\site-packages\flask\_compat.py", line 35, in reraise
    raise value
  File "c:\users\dell\desktop\microblog\venv\lib\site-packages\flask\app.py", line 1813, in full_dispatch_request
    rv = self.dispatch_request()
  File "c:\users\dell\desktop\microblog\venv\lib\site-packages\flask\app.py", line 1799, in dispatch_request
    return self.view_functions[rule.endpoint](**req.view_args)
  File "c:\users\dell\desktop\microblog\venv\lib\site-packages\flask_login\utils.py", line 261, in decorated_view
    return func(*args, **kwargs)
  File "C:\Users\DELL\Desktop\microblog\app\routes.py", line 88, in edit_profile
    form=EditprofileForm(current_user.username,)
  File "c:\users\dell\desktop\microblog\venv\lib\site-packages\wtforms\form.py", line 212, in __call__
    return type.__call__(cls, *args, **kwargs)
  File "C:\Users\DELL\Desktop\microblog\app\forms.py", line 38, in __init__
    super(EditProfileForm, self).__init__(args, **kwargs)
NameError: name 'EditProfileForm' is not defined
2019-07-16 08:15:23,646 ERROR: Exception on /edit_profile.html [GET] [in c:\users\dell\desktop\microblog\venv\lib\site-packages\flask\app.py:1761]
Traceback (most recent call last):
  File "c:\users\dell\desktop\microblog\venv\lib\site-packages\flask\app.py", line 2292, in wsgi_app
    response = self.full_dispatch_request()
  File "c:\users\dell\desktop\microblog\venv\lib\site-packages\flask\app.py", line 1815, in full_dispatch_request
    rv = self.handle_user_exception(e)
  File "c:\users\dell\desktop\microblog\venv\lib\site-packages\flask\app.py", line 1718, in handle_user_exception
    reraise(exc_type, exc_value, tb)
  File "c:\users\dell\desktop\microblog\venv\lib\site-packages\flask\_compat.py", line 35, in reraise
    raise value
  File "c:\users\dell\desktop\microblog\venv\lib\site-packages\flask\app.py", line 1813, in full_dispatch_request
    rv = self.dispatch_request()
  File "c:\users\dell\desktop\microblog\venv\lib\site-packages\flask\app.py", line 1799, in dispatch_request
    return self.view_functions[rule.endpoint](**req.view_args)
  File "c:\users\dell\desktop\microblog\venv\lib\site-packages\flask_login\utils.py", line 261, in decorated_view
    return func(*args, **kwargs)
  File "C:\Users\DELL\Desktop\microblog\app\routes.py", line 88, in edit_profile
    form=EditprofileForm(current_user.username,)
  File "c:\users\dell\desktop\microblog\venv\lib\site-packages\wtforms\form.py", line 212, in __call__
    return type.__call__(cls, *args, **kwargs)
  File "C:\Users\DELL\Desktop\microblog\app\forms.py", line 38, in __init__
    super(EditProfileForm, self).__init__(args, **kwargs)
NameError: name 'EditProfileForm' is not defined
2019-07-16 08:16:09,900 INFO: Microblog startup [in C:\Users\DELL\Desktop\microblog\app\__init__.py:43]
