2019-08-03 21:51:42,814 ERROR Exception on /reset_password_request [GET] [in c:\users\user\documents\microblog\venv\lib\site-packages\flask\app.py:(lineno)d]
Traceback (most recent call last):
  File "c:\users\user\documents\microblog\venv\lib\site-packages\flask\app.py", line 2292, in wsgi_app
    response = self.full_dispatch_request()
  File "c:\users\user\documents\microblog\venv\lib\site-packages\flask\app.py", line 1815, in full_dispatch_request
    rv = self.handle_user_exception(e)
  File "c:\users\user\documents\microblog\venv\lib\site-packages\flask\app.py", line 1718, in handle_user_exception
    reraise(exc_type, exc_value, tb)
  File "c:\users\user\documents\microblog\venv\lib\site-packages\flask\_compat.py", line 35, in reraise
    raise value
  File "c:\users\user\documents\microblog\venv\lib\site-packages\flask\app.py", line 1813, in full_dispatch_request
    rv = self.dispatch_request()
  File "c:\users\user\documents\microblog\venv\lib\site-packages\flask\app.py", line 1799, in dispatch_request
    return self.view_functions[rule.endpoint](**req.view_args)
  File "C:\Users\user\Documents\microblog\app\routes.py", line 268, in reset_password_request
    return render_template('reset_password_request.html', title='Reset Password', form=form)
  File "c:\users\user\documents\microblog\venv\lib\site-packages\flask\templating.py", line 135, in render_template
    context, ctx.app)
  File "c:\users\user\documents\microblog\venv\lib\site-packages\flask\templating.py", line 117, in _render
    rv = template.render(context)
  File "c:\users\user\documents\microblog\venv\lib\site-packages\jinja2\asyncsupport.py", line 76, in render
    return original_render(self, *args, **kwargs)
  File "c:\users\user\documents\microblog\venv\lib\site-packages\jinja2\environment.py", line 1008, in render
    return self.environment.handle_exception(exc_info, True)
  File "c:\users\user\documents\microblog\venv\lib\site-packages\jinja2\environment.py", line 780, in handle_exception
    reraise(exc_type, exc_value, tb)
  File "c:\users\user\documents\microblog\venv\lib\site-packages\jinja2\_compat.py", line 37, in reraise
    raise value.with_traceback(tb)
  File "C:\Users\user\Documents\microblog\app\templates\reset_password_request.html", line 1, in top-level template code
    {% extends "base.html" %}
  File "C:\Users\user\Documents\microblog\app\templates\base.html", line 36, in top-level template code
    {% block content %}{% endblock %}
  File "C:\Users\user\Documents\microblog\app\templates\reset_password_request.html", line 8, in block "content"
    {{ form.email.label }}<br>
  File "c:\users\user\documents\microblog\venv\lib\site-packages\jinja2\environment.py", line 430, in getattr
    return getattr(obj, attribute)
jinja2.exceptions.UndefinedError: 'app.forms.ResetPasswordForm object' has no attribute 'email'
2019-08-03 21:51:53,896 INFO Microblog startup [in C:\Users\user\Documents\microblog\app\__init__.py:(lineno)d]
2019-08-03 21:52:00,382 ERROR Exception on /reset_password_request [GET] [in c:\users\user\documents\microblog\venv\lib\site-packages\flask\app.py:(lineno)d]
Traceback (most recent call last):
  File "c:\users\user\documents\microblog\venv\lib\site-packages\flask\app.py", line 2292, in wsgi_app
    response = self.full_dispatch_request()
  File "c:\users\user\documents\microblog\venv\lib\site-packages\flask\app.py", line 1815, in full_dispatch_request
    rv = self.handle_user_exception(e)
  File "c:\users\user\documents\microblog\venv\lib\site-packages\flask\app.py", line 1718, in handle_user_exception
    reraise(exc_type, exc_value, tb)
  File "c:\users\user\documents\microblog\venv\lib\site-packages\flask\_compat.py", line 35, in reraise
    raise value
  File "c:\users\user\documents\microblog\venv\lib\site-packages\flask\app.py", line 1813, in full_dispatch_request
    rv = self.dispatch_request()
  File "c:\users\user\documents\microblog\venv\lib\site-packages\flask\app.py", line 1799, in dispatch_request
    return self.view_functions[rule.endpoint](**req.view_args)
  File "C:\Users\user\Documents\microblog\app\routes.py", line 268, in reset_password_request
    return render_template('reset_password_request.html', title='Reset Password', form=form)
  File "c:\users\user\documents\microblog\venv\lib\site-packages\flask\templating.py", line 135, in render_template
    context, ctx.app)
  File "c:\users\user\documents\microblog\venv\lib\site-packages\flask\templating.py", line 117, in _render
    rv = template.render(context)
  File "c:\users\user\documents\microblog\venv\lib\site-packages\jinja2\asyncsupport.py", line 76, in render
    return original_render(self, *args, **kwargs)
  File "c:\users\user\documents\microblog\venv\lib\site-packages\jinja2\environment.py", line 1008, in render
    return self.environment.handle_exception(exc_info, True)
  File "c:\users\user\documents\microblog\venv\lib\site-packages\jinja2\environment.py", line 780, in handle_exception
    reraise(exc_type, exc_value, tb)
  File "c:\users\user\documents\microblog\venv\lib\site-packages\jinja2\_compat.py", line 37, in reraise
    raise value.with_traceback(tb)
  File "C:\Users\user\Documents\microblog\app\templates\reset_password_request.html", line 1, in top-level template code
    {% extends "base.html" %}
  File "C:\Users\user\Documents\microblog\app\templates\base.html", line 36, in top-level template code
    {% block content %}{% endblock %}
  File "C:\Users\user\Documents\microblog\app\templates\reset_password_request.html", line 8, in block "content"
    {{ form.email.label }}<br>
  File "c:\users\user\documents\microblog\venv\lib\site-packages\jinja2\environment.py", line 430, in getattr
    return getattr(obj, attribute)
jinja2.exceptions.UndefinedError: 'app.forms.ResetPasswordForm object' has no attribute 'email'
2019-08-03 21:54:25,091 INFO Microblog startup [in C:\Users\user\Documents\microblog\app\__init__.py:(lineno)d]
2019-08-03 21:55:02,677 INFO Microblog startup [in C:\Users\user\Documents\microblog\app\__init__.py:(lineno)d]
2019-08-03 21:55:16,033 ERROR Exception on /reset_password_request [POST] [in c:\users\user\documents\microblog\venv\lib\site-packages\flask\app.py:(lineno)d]
Traceback (most recent call last):
  File "c:\users\user\documents\microblog\venv\lib\site-packages\flask\app.py", line 2292, in wsgi_app
    response = self.full_dispatch_request()
  File "c:\users\user\documents\microblog\venv\lib\site-packages\flask\app.py", line 1815, in full_dispatch_request
    rv = self.handle_user_exception(e)
  File "c:\users\user\documents\microblog\venv\lib\site-packages\flask\app.py", line 1718, in handle_user_exception
    reraise(exc_type, exc_value, tb)
  File "c:\users\user\documents\microblog\venv\lib\site-packages\flask\_compat.py", line 35, in reraise
    raise value
  File "c:\users\user\documents\microblog\venv\lib\site-packages\flask\app.py", line 1813, in full_dispatch_request
    rv = self.dispatch_request()
  File "c:\users\user\documents\microblog\venv\lib\site-packages\flask\app.py", line 1799, in dispatch_request
    return self.view_functions[rule.endpoint](**req.view_args)
  File "C:\Users\user\Documents\microblog\app\routes.py", line 265, in reset_password_request
    send_password_reset_email(user)
  File "C:\Users\user\Documents\microblog\app\email.py", line 20, in send_password_reset_email
    user=user, token=token))
  File "C:\Users\user\Documents\microblog\app\email.py", line 10, in send_email
    mail.send(msg)
  File "c:\users\user\documents\microblog\venv\lib\site-packages\flask_mail.py", line 491, in send
    with self.connect() as connection:
  File "c:\users\user\documents\microblog\venv\lib\site-packages\flask_mail.py", line 144, in __enter__
    self.host = self.configure_host()
  File "c:\users\user\documents\microblog\venv\lib\site-packages\flask_mail.py", line 158, in configure_host
    host = smtplib.SMTP(self.mail.server, self.mail.port)
  File "C:\Users\user\AppData\Local\Programs\Python\Python37\lib\smtplib.py", line 251, in __init__
    (code, msg) = self.connect(host, port)
  File "C:\Users\user\AppData\Local\Programs\Python\Python37\lib\smtplib.py", line 336, in connect
    self.sock = self._get_socket(host, port, self.timeout)
  File "C:\Users\user\AppData\Local\Programs\Python\Python37\lib\smtplib.py", line 307, in _get_socket
    self.source_address)
  File "C:\Users\user\AppData\Local\Programs\Python\Python37\lib\socket.py", line 707, in create_connection
    for res in getaddrinfo(host, port, 0, SOCK_STREAM):
  File "C:\Users\user\AppData\Local\Programs\Python\Python37\lib\socket.py", line 748, in getaddrinfo
    for res in _socket.getaddrinfo(host, port, family, type, proto, flags):
socket.gaierror: [Errno 11001] getaddrinfo failed
2019-08-03 21:55:32,979 INFO Microblog startup [in C:\Users\user\Documents\microblog\app\__init__.py:(lineno)d]
